<?xml version="1.0" encoding="utf-8"?>
<!-- This URDF was automatically created by SolidWorks to URDF Exporter! Originally created by Stephen Brawner (brawner@gmail.com) 
     Commit Version: 1.6.0-4-g7f85cfe  Build Version: 1.6.7995.38578
     For more information, please see http://wiki.ros.org/sw_urdf_exporter -->
<robot
  name="robot4w">
  <link
    name="base_link">
    <inertial>
      <origin
        xyz="0.0078795 0.00077459 0.041095"
        rpy="0 0 0" />
      <mass
        value="3" />
      <inertia
        ixx="0.0041187"
        ixy="5.5823E-06"
        ixz="3.2535E-15"
        iyy="0.012702"
        iyz="-1.2196E-18"
        izz="0.016603" />
    </inertial>
    <visual>
      <origin
        xyz="0 0 0"
        rpy="0 0 0" />
      <geometry>
        <mesh
          filename="package://robot4w/meshes/base_link.STL" />
      </geometry>
      <material
        name="">
        <color
          rgba="0.79216 0.81961 0.93333 1" />
      </material>
    </visual>
    <collision>
      <origin
        xyz="0 0 0"
        rpy="0 0 0" />
      <geometry>
        <mesh
          filename="package://robot4w/meshes/base_link.STL" />
      </geometry>
    </collision>
  </link>
  <link
    name="rodakiribwh_Link">
    <inertial>
      <origin
        xyz="1.6966E-08 -0.023829 -1.0182E-07"
        rpy="0 0 0" />
      <mass
        value="0.5" />
      <inertia
        ixx="4.6952E-05"
        ixy="-1.6211E-18"
        ixz="-2.0117E-17"
        iyy="6.4174E-05"
        iyz="9.0708E-18"
        izz="4.6952E-05" />
    </inertial>
    <visual>
      <origin
        xyz="0 0 0"
        rpy="0 0 0" />
      <geometry>
        <mesh
          filename="package://robot4w/meshes/rodakiribwh_Link.STL" />
      </geometry>
      <material
        name="">
        <color
          rgba="0.79216 0.81961 0.93333 1" />
      </material>
    </visual>
    <collision>
      <origin
        xyz="0 0 0"
        rpy="0 0 0" />
      <geometry>
        <mesh
          filename="package://robot4w/meshes/rodakiribwh_Link.STL" />
      </geometry>
    </collision>
  </link>
  <joint
    name="rodabwhkiri"
    type="continuous">
    <origin
      xyz="-0.2 0.18325 0.022"
      rpy="0 -0.084622 0" />
    <parent
      link="base_link" />
    <child
      link="rodakiribwh_Link" />
    <axis
      xyz="0 -1 0" />
  </joint>
  <link
    name="rodakiriats_Link">
    <inertial>
      <origin
        xyz="7.5112E-08 -0.023829 -7.08E-08"
        rpy="0 0 0" />
      <mass
        value="0.5" />
      <inertia
        ixx="4.6952E-05"
        ixy="-6.7926E-18"
        ixz="-8.8395E-18"
        iyy="6.4174E-05"
        iyz="6.2199E-18"
        izz="4.6952E-05" />
    </inertial>
    <visual>
      <origin
        xyz="0 0 0"
        rpy="0 0 0" />
      <geometry>
        <mesh
          filename="package://robot4w/meshes/rodakiriats_Link.STL" />
      </geometry>
      <material
        name="">
        <color
          rgba="0.79216 0.81961 0.93333 1" />
      </material>
    </visual>
    <collision>
      <origin
        xyz="0 0 0"
        rpy="0 0 0" />
      <geometry>
        <mesh
          filename="package://robot4w/meshes/rodakiriats_Link.STL" />
      </geometry>
    </collision>
  </link>
  <joint
    name="rodaatskir"
    type="continuous">
    <origin
      xyz="0.2 0.18325 0.022"
      rpy="0 0 0" />
    <parent
      link="base_link" />
    <child
      link="rodakiriats_Link" />
    <axis
      xyz="0 -1 0" />
  </joint>
  <link
    name="rodakananatas_Link">
    <inertial>
      <origin
        xyz="-7.08E-08 0.023829 7.5112E-08"
        rpy="0 0 0" />
      <mass
        value="0.5" />
      <inertia
        ixx="4.6952E-05"
        ixy="-6.2062E-18"
        ixz="-8.8411E-18"
        iyy="6.4174E-05"
        iyz="6.7654E-18"
        izz="4.6952E-05" />
    </inertial>
    <visual>
      <origin
        xyz="0 0 0"
        rpy="0 0 0" />
      <geometry>
        <mesh
          filename="package://robot4w/meshes/rodakananatas_Link.STL" />
      </geometry>
      <material
        name="">
        <color
          rgba="0.79216 0.81961 0.93333 1" />
      </material>
    </visual>
    <collision>
      <origin
        xyz="0 0 0"
        rpy="0 0 0" />
      <geometry>
        <mesh
          filename="package://robot4w/meshes/rodakananatas_Link.STL" />
      </geometry>
    </collision>
  </link>
  <joint
    name="rodaataskanan"
    type="continuous">
    <origin
      xyz="0.2 -0.18325 0.022"
      rpy="0 0 0" />
    <parent
      link="base_link" />
    <child
      link="rodakananatas_Link" />
    <axis
      xyz="0 1 0" />
  </joint>
  <link
    name="rodakananbwh_Link">
    <inertial>
      <origin
        xyz="-7.08E-08 0.023421 -7.5112E-08"
        rpy="0 0 0" />
      <mass
        value="0.5" />
      <inertia
        ixx="4.6952E-05"
        ixy="6.2388E-18"
        ixz="8.8426E-18"
        iyy="6.4174E-05"
        iyz="6.7595E-18"
        izz="4.6952E-05" />
    </inertial>
    <visual>
      <origin
        xyz="0 0 0"
        rpy="0 0 0" />
      <geometry>
        <mesh
          filename="package://robot4w/meshes/rodakananbwh_Link.STL" />
      </geometry>
      <material
        name="">
        <color
          rgba="0.79216 0.81961 0.93333 1" />
      </material>
    </visual>
    <collision>
      <origin
        xyz="0 0 0"
        rpy="0 0 0" />
      <geometry>
        <mesh
          filename="package://robot4w/meshes/rodakananbwh_Link.STL" />
      </geometry>
    </collision>
  </link>
  <joint
    name="rodabwhkanan"
    type="continuous">
    <origin
      xyz="-0.2 -0.18325 0.022"
      rpy="0 0 0" />
    <parent
      link="base_link" />
    <child
      link="rodakananbwh_Link" />
    <axis
      xyz="0 1 0" />
  </joint>
  <link
    name="sensordepan_Link">
    <inertial>
      <origin
        xyz="0.0036835 3.0075E-05 0.00041581"
        rpy="0 0 0" />
      <mass
        value="0.002" />
      <inertia
        ixx="1.1247E-06"
        ixy="2.5349E-13"
        ixz="-2.9986E-09"
        iyy="2.0431E-07"
        iyz="1.9203E-14"
        izz="1.0828E-06" />
    </inertial>
    <visual>
      <origin
        xyz="0 0 0"
        rpy="0 0 0" />
      <geometry>
        <mesh
          filename="package://robot4w/meshes/sensordepan_Link.STL" />
      </geometry>
      <material
        name="">
        <color
          rgba="0.10196 0.10196 0.10196 1" />
      </material>
    </visual>
    <collision>
      <origin
        xyz="0 0 0"
        rpy="0 0 0" />
      <geometry>
        <mesh
          filename="package://robot4w/meshes/sensordepan_Link.STL" />
      </geometry>
    </collision>
  </link>
  <joint
    name="depans"
    type="fixed">
    <origin
      xyz="0.23209 0.0059934 0.009585"
      rpy="0 0 0" />
    <parent
      link="base_link" />
    <child
      link="sensordepan_Link" />
    <axis
      xyz="0 0 0" />
  </joint>
  <link
    name="sensorkiri_Link">
    <inertial>
      <origin
        xyz="0.0036835 3.0075E-05 0.00041581"
        rpy="0 0 0" />
      <mass
        value="0.002" />
      <inertia
        ixx="1.1247E-06"
        ixy="2.5349E-13"
        ixz="-2.9986E-09"
        iyy="2.0431E-07"
        iyz="1.9203E-14"
        izz="1.0828E-06" />
    </inertial>
    <visual>
      <origin
        xyz="0 0 0"
        rpy="0 0 0" />
      <geometry>
        <mesh
          filename="package://robot4w/meshes/sensorkiri_Link.STL" />
      </geometry>
      <material
        name="">
        <color
          rgba="0.10196 0.10196 0.10196 1" />
      </material>
    </visual>
    <collision>
      <origin
        xyz="0 0 0"
        rpy="0 0 0" />
      <geometry>
        <mesh
          filename="package://robot4w/meshes/sensorkiri_Link.STL" />
      </geometry>
    </collision>
  </link>
  <joint
    name="sensork"
    type="fixed">
    <origin
      xyz="-0.0048711 0.1233 0.009585"
      rpy="0 0 1.5708" />
    <parent
      link="base_link" />
    <child
      link="sensorkiri_Link" />
    <axis
      xyz="0 0 0" />
  </joint>
  <link
    name="sensorkanan_Link">
    <inertial>
      <origin
        xyz="0.0036835 3.0075E-05 0.00041581"
        rpy="0 0 0" />
      <mass
        value="0.002" />
      <inertia
        ixx="1.1247E-06"
        ixy="2.5349E-13"
        ixz="-2.9986E-09"
        iyy="2.0431E-07"
        iyz="1.9203E-14"
        izz="1.0828E-06" />
    </inertial>
    <visual>
      <origin
        xyz="0 0 0"
        rpy="0 0 0" />
      <geometry>
        <mesh
          filename="package://robot4w/meshes/sensorkanan_Link.STL" />
      </geometry>
      <material
        name="">
        <color
          rgba="0.10196 0.10196 0.10196 1" />
      </material>
    </visual>
    <collision>
      <origin
        xyz="0 0 0"
        rpy="0 0 0" />
      <geometry>
        <mesh
          filename="package://robot4w/meshes/sensorkanan_Link.STL" />
      </geometry>
    </collision>
  </link>
  <joint
    name="sensork"
    type="fixed">
    <origin
      xyz="0.0019567 -0.12532 0.009585"
      rpy="0 0 -1.5708" />
    <parent
      link="base_link" />
    <child
      link="sensorkanan_Link" />
    <axis
      xyz="0 0 0" />
  </joint>
  <link
    name="sesorbelakng_Link">
    <inertial>
      <origin
        xyz="0.0036835 3.0075E-05 0.00041581"
        rpy="0 0 0" />
      <mass
        value="0.002" />
      <inertia
        ixx="1.1247E-06"
        ixy="2.5349E-13"
        ixz="-2.9986E-09"
        iyy="2.0431E-07"
        iyz="1.9203E-14"
        izz="1.0828E-06" />
    </inertial>
    <visual>
      <origin
        xyz="0 0 0"
        rpy="0 0 0" />
      <geometry>
        <mesh
          filename="package://robot4w/meshes/sesorbelakng_Link.STL" />
      </geometry>
      <material
        name="">
        <color
          rgba="0.10196 0.10196 0.10196 1" />
      </material>
    </visual>
    <collision>
      <origin
        xyz="0 0 0"
        rpy="0 0 0" />
      <geometry>
        <mesh
          filename="package://robot4w/meshes/sesorbelakng_Link.STL" />
      </geometry>
    </collision>
  </link>
  <joint
    name="sbelakang"
    type="fixed">
    <origin
      xyz="-0.22973 0.0056954 0.009585"
      rpy="0 0 -3.1416" />
    <parent
      link="base_link" />
    <child
      link="sesorbelakng_Link" />
    <axis
      xyz="0 0 0" />
  </joint>
</robot>